Workbook

Sheet Bill Input
A1: ⚡ ENERGYBAE — Solar Load Calculator
A2: Electricity Bill Data Extraction — MSEDCL / Maharashtra
A3: 🟡 Yellow = Input cells (fill from bill) 🟠 Orange = Auto-calculated 🔵 Blue = Output / Results
A4: A. CUSTOMER INFORMATION
A5: Consumer Name | C5: Consumer Number
A6: Address | C6: Tariff Category
A7: Discom / Utility | B7: MSEDCL | C7: Division / Sub-div
A8: Bill Month | C8: Bill Date
A9: Meter Number | C9: Sanctioned Load (kW)
A11: B. MONTHLY CONSUMPTION (Units / kWh)
A12: Month | B12: Jan | C12: Feb | D12: Mar | E12: Apr | F12: May | G12: Jun | H12: Jul | I12: Aug | J12: Sep | K12: Oct | L12: Nov | M12: Dec
A13: Units (kWh)
A14: Average Monthly (kWh) | B14: =IFERROR(AVERAGE(B13:M13),"") | C14: Peak Month (kWh) | D14: =IFERROR(MAX(B13:M13),"")
A16: C. BILL DETAILS & TARIFF
A17: Total Units Consumed (Latest Bill) | C17: Bill Amount (₹)
A18: Fixed / Demand Charges (₹) | C18: Electricity Duty (₹)
A19: Fuel Adjustment Charge (₹) | C19: Meter Rent / Other (₹)
A20: Subsidies / Rebate (₹) | C20: Net Payable Amount (₹)
A21: Tariff Slab (e.g. LT-II) | C21: Rate per Unit (₹/kWh)
A22: Connected Load (kW) | C22: Power Factor

Sheet Solar Sizing
A1: ⚡ ENERGYBAE — Solar System Sizing Engine
A2: Auto-calculated from Bill Input sheet — do not manually edit formula cells
A3: 1. SYSTEM ASSUMPTIONS (Editable)
A4: Peak Sun Hours (PSH) — Maharashtra | B4: 4.5 | C4: hrs/day | D4: Avg solar irradiance for Pune/MH region
A5: System Efficiency | B5: 0.8 | D5: Accounts for inverter, wiring, soiling losses
A6: Performance Ratio | B6: 0.75 | D6: Typical PR for rooftop systems in India
A7: Cost per kWp (On-Grid) | B7: 45000 | C7: ₹/kWp | D7: Market rate as of 2024-25; adjust as needed
A8: Cost per kWp (Off-Grid/Hybrid) | B8: 65000 | C8: ₹/kWp | D8: Includes battery storage
A9: Annual Degradation Rate | B9: 0.007 | D9: 0.7% per year — standard poly/mono panels
A10: Net Metering Applicable? | B10: Yes | D10: Yes/No — affects savings calculation
A11: Grid Electricity Rate (₹/kWh) | B11: 9 | C11: ₹/kWh | D11: Pull from Bill Input D21 or enter manually
A12: Annual Electricity Escalation | B12: 0.05 | D12: 5% YoY tariff increase assumption
A13: System Lifespan | B13: 25 | C13: years | D13: Standard warranty period
A14: Subsidy (PM Surya Ghar scheme) | B14: 0.3 | D14: 30% central govt subsidy on system cost
A16: 2. ENERGY DEMAND ANALYSIS
A17: Average Monthly Consumption (kWh) | B17: ='Bill Input'!B14 | C17: kWh/month | D17: Pulled from Bill Input — average of 12 months
A18: Peak Monthly Consumption (kWh) | B18: ='Bill Input'!D14 | C18: kWh/month | D18: Max month — used for sizing to avoid shortfall
A19: Daily Energy Requirement (avg) | B19: =IFERROR(B17/30,"") | C19: kWh/day | D19: B17 / 30 days
A20: Daily Energy Requirement (peak) | B20: =IFERROR(B18/30,"") | C20: kWh/day | D20: B18 / 30 days — conservative sizing basis
A21: Annual Energy Consumption | B21: =IFERROR(B17*12,"") | C21: kWh/year | D21: Annualised from average monthly
A23: 3. RECOMMENDED SOLAR SYSTEM SIZE
A24: Solar Capacity Required (avg basis) | B24: =IFERROR(B19/(B4*B5),"") | C24: kWp | D24: Daily kWh ÷ (PSH × System Efficiency)
A25: Solar Capacity Required (peak basis) | B25: =IFERROR(B20/(B4*B5),"") | C25: kWp | D25: Peak daily kWh ÷ (PSH × System Efficiency) — recommended
A26: Recommended System Size (rounded) | B26: =IFERROR(CEILING(B25,1),"") | C26: kWp | D26: Rounded up to nearest 1 kWp
A27: Number of Solar Panels (400W) | B27: =IFERROR(CEILING(B26*1000/400,1),"") | C27: panels | D27: Assuming 400W monocrystalline panels
A28: Rooftop Area Required | B28: =IFERROR(B26*10,"") | C28: sq. meters | D28: ~10 sq.m per kWp rule of thumb
A29: Annual Solar Generation (Year 1) | B29: =IFERROR(B26*B4*365*B6,"") | C29: kWh/year | D29: Capacity × PSH × 365 × Performance Ratio
A30: Solar Coverage Ratio | B30: =IFERROR(B29/B21,"") | D30: Solar generation ÷ Annual consumption (aim >0.9)
A32: 4. FINANCIAL ANALYSIS
A33: System Cost (On-Grid, before subsidy) | B33: =IFERROR(B26*B7,"") | C33: ₹ | D33: Recommended size × cost per kWp
A34: Subsidy Amount | B34: =IFERROR(B33*B14,"") | C34: ₹ | D34: PM Surya Ghar or applicable state subsidy
A35: Net System Cost (after subsidy) | B35: =IFERROR(B33-B34,"") | C35: ₹ | D35: Customer's actual investment
A36: Annual Electricity Bill (current) | B36: ='Bill Input'!D20*12 | C36: ₹/year | D36: Net Payable (monthly) × 12
A37: Annual Savings — Year 1 | B37: =IFERROR(B29*B11,"") | C37: ₹/year | D37: Solar generation × grid rate
A38: Simple Payback Period | B38: =IFERROR(B35/B37,"") | C38: years | D38: Net cost ÷ Year-1 savings
A39: 25-Year Cumulative Savings | B39: =IFERROR(B37*((1-(1+B12)^(-B13))/B12)*(1+B12),"") | C39: ₹ | D39: NPV of escalating savings over lifespan
A40: ROI (25 years) | B40: =IFERROR((B39-B35)/B35,"") | D40: Total return on investment
A42: 5. ENVIRONMENTAL IMPACT
A43: CO₂ Avoided per Year | B43: =IFERROR(B29*0.82,"") | C43: kg CO₂/year | D43: India grid emission factor: 0.82 kg CO₂/kWh (CEA 2023)
A44: Trees Equivalent per Year | B44: =IFERROR(B43/21,"") | C44: trees | D44: ~21 kg CO₂ absorbed per tree per year
...

Sheet Customer Report
B1: ENERGYBAE — Solar Proposal Summary
B2: www.energybae.in | +91 9112233120 | energybae.co@gmail.com
B4: CUSTOMER DETAILS
B5: Customer Name | C5: ='Bill Input'!B5
B6: Consumer Number | C6: ='Bill Input'!D5
B7: Address | C7: ='Bill Input'!B6
B8: Tariff Category | C8: ='Bill Input'!D6
B10: CONSUMPTION SUMMARY
B11: Average Monthly Usage | C11: ='Solar Sizing'!B17
B12: Peak Monthly Usage | C12: ='Solar Sizing'!B18
B13: Current Annual Bill | C13: ='Solar Sizing'!B36
B15: RECOMMENDED SOLAR SOLUTION
B16: Recommended System Size | C16: ='Solar Sizing'!B26
B17: Number of Panels (400W) | C17: ='Solar Sizing'!B27
B18: Rooftop Area Required | C18: ='Solar Sizing'!B28
B19: Annual Generation | C19: ='Solar Sizing'!B29
B21: FINANCIAL SUMMARY
B22: Total System Cost | C22: ='Solar Sizing'!B33
B23: Govt. Subsidy | C23: ='Solar Sizing'!B34
B24: Net Investment | C24: ='Solar Sizing'!B35
B25: Annual Savings (Year 1) | C25: ='Solar Sizing'!B37
B26: Payback Period | C26: ='Solar Sizing'!B38
B27: 25-Year Savings | C27: ='Solar Sizing'!B39
B28: Return on Investment | C28: ='Solar Sizing'!B40
B30: ENVIRONMENTAL IMPACT
B31: CO₂ Avoided per Year | C31: ='Solar Sizing'!B43
B32: Equivalent Trees Planted | C32: ='Solar Sizing'!B44
B34: This is an AI-generated estimate. Final sizing subject to site survey. Valid 30 days from date of report.
